<?xml version="1.0" encoding="utf-8"?>
<!-- This URDF was automatically created by SolidWorks to URDF Exporter! Originally created by Stephen Brawner (brawner@gmail.com) 
     Commit Version: 1.5.1-0-g916b5db  Build Version: 1.5.7152.31018
     For more information, please see http://wiki.ros.org/sw_urdf_exporter -->
<robot
  name="abot">
  <link
    name="abot_base">
    <inertial>
      <origin
        xyz="-0.0199717106372355 -0.00112336813520822 0.0535689050352355"
        rpy="0 0 0" />
      <mass
        value="0.537364562401972" />
      <inertia
        ixx="0.000610038059488051"
        ixy="-1.71155362812322E-06"
        ixz="-1.10441012108461E-05"
        iyy="0.000612338689908626"
        iyz="-8.13597159323162E-09"
        izz="0.00112946665905071" />
    </inertial>
    <visual>
      <origin
        xyz="0 0 0"
        rpy="0 0 0" />
      <geometry>
        <mesh
          filename="package://abot/meshes/abot_base.STL" />
      </geometry>
      <material
        name="">
        <color
          rgba="0.752941176470588 0.752941176470588 0.752941176470588 1" />
      </material>
    </visual>
    <collision>
      <origin
        xyz="0 0 0"
        rpy="0 0 0" />
      <geometry>
        <mesh
          filename="package://abot/meshes/abot_base.STL" />
      </geometry>
    </collision>
  </link>
  <link
    name="abot_left_wheel">
    <inertial>
      <origin
        xyz="1.925477288553E-10 0.000565763151060841 -1.0414403540937E-10"
        rpy="0 0 0" />
      <mass
        value="0.0504636002883634" />
      <inertia
        ixx="2.07010058324571E-05"
        ixy="-3.80886681423744E-14"
        ixz="1.35840784603396E-15"
        iyy="3.58274339853361E-05"
        iyz="2.18379823025868E-15"
        izz="2.07008063139734E-05" />
    </inertial>
    <visual>
      <origin
        xyz="0 0 0"
        rpy="0 0 0" />
      <geometry>
        <mesh
          filename="package://abot/meshes/abot_left_wheel.STL" />
      </geometry>
      <material
        name="">
        <color
          rgba="1 1 0 1" />
      </material>
    </visual>
    <collision>
      <origin
        xyz="0 0 0"
        rpy="0 0 0" />
      <geometry>
        <mesh
          filename="package://abot/meshes/abot_left_wheel.STL" />
      </geometry>
    </collision>
  </link>
  <joint
    name="left_wheel_to_base"
    type="continuous">
    <origin
      xyz="0 0.068 0.0145"
      rpy="0 0 0" />
    <parent
      link="abot_base" />
    <child
      link="abot_left_wheel" />
    <axis
      xyz="0 1 0" />
  </joint>
  <link
    name="abot_right_wheel">
    <inertial>
      <origin
        xyz="1.92547726563493E-10 -0.000565763151060827 1.04144037144094E-10"
        rpy="0 0 0" />
      <mass
        value="0.0504636002883635" />
      <inertia
        ixx="2.07010058324571E-05"
        ixy="3.80886687364398E-14"
        ixz="-1.35840655335235E-15"
        iyy="3.58274339853362E-05"
        iyz="2.18379794855005E-15"
        izz="2.07008063139734E-05" />
    </inertial>
    <visual>
      <origin
        xyz="0 0 0"
        rpy="0 0 0" />
      <geometry>
        <mesh
          filename="package://abot/meshes/abot_right_wheel.STL" />
      </geometry>
      <material
        name="">
        <color
          rgba="1 1 0 1" />
      </material>
    </visual>
    <collision>
      <origin
        xyz="0 0 0"
        rpy="0 0 0" />
      <geometry>
        <mesh
          filename="package://abot/meshes/abot_right_wheel.STL" />
      </geometry>
    </collision>
  </link>
  <joint
    name="right_wheel_to_base"
    type="continuous">
    <origin
      xyz="0 -0.0680000000000001 0.0144999999999995"
      rpy="0 0 0" />
    <parent
      link="abot_base" />
    <child
      link="abot_right_wheel" />
    <axis
      xyz="0 1 0" />
  </joint>
  <link
    name="abot_caster_wheel">
    <inertial>
      <origin
        xyz="0 1.6073E-19 0"
        rpy="0 0 0" />
      <mass
        value="0.011207" />
      <inertia
        ixx="2.1965E-07"
        ixy="-1.5533E-55"
        ixz="-1.9776E-56"
        iyy="2.1965E-07"
        iyz="-2.2674E-40"
        izz="2.1965E-07" />
    </inertial>
    <visual>
      <origin
        xyz="0 0 0"
        rpy="0 0 0" />
      <geometry>
        <mesh
          filename="package://abot/meshes/abot_caster_wheel.STL" />
      </geometry>
      <material
        name="">
        <color
          rgba="0.52941 0.54902 0.54902 1" />
      </material>
    </visual>
    <collision>
      <origin
        xyz="0 0 0"
        rpy="0 0 0" />
      <geometry>
        <mesh
          filename="package://abot/meshes/abot_caster_wheel.STL" />
      </geometry>
    </collision>
  </link>
  <joint
    name="caster_wheel_to_base"
    type="fixed">
    <origin
      xyz="-0.078 0 -0.011"
      rpy="0 0 0" />
    <parent
      link="abot_base" />
    <child
      link="abot_caster_wheel" />
    <axis
      xyz="0 0 0" />
  </joint>
  <link
    name="abot_lidar">
    <inertial>
      <origin
        xyz="0 0 0"
        rpy="0 0 0" />
      <mass
        value="0" />
      <inertia
        ixx="0"
        ixy="0"
        ixz="0"
        iyy="0"
        iyz="0"
        izz="0" />
    </inertial>
    <visual>
      <origin
        xyz="0 0 0"
        rpy="0 0 0" />
      <geometry>
        <mesh
          filename="package://abot/meshes/abot_lidar.STL" />
      </geometry>
      <material
        name="">
        <color
          rgba="1 1 1 1" />
      </material>
    </visual>
    <collision>
      <origin
        xyz="0 0 0"
        rpy="0 0 0" />
      <geometry>
        <mesh
          filename="package://abot/meshes/abot_lidar.STL" />
      </geometry>
    </collision>
  </link>
  <joint
    name="lidar_to_base"
    type="fixed">
    <origin
      xyz="-0.01 0 0.1319"
      rpy="0 0 3.1416" />
    <parent
      link="abot_base" />
    <child
      link="abot_lidar" />
    <axis
      xyz="0 0 0" />
  </joint>
</robot>