<?xml version="1.0" encoding="utf-8"?>
<!-- This URDF was automatically created by SolidWorks to URDF Exporter! Originally created by Stephen Brawner (brawner@gmail.com) 
     Commit Version: 1.5.1-0-g916b5db  Build Version: 1.5.7152.31018
     For more information, please see http://wiki.ros.org/sw_urdf_exporter -->
<robot
  name="ABOT">
  <link
    name="base_link">
    <inertial>
      <origin
        xyz="1.09526911933665E-13 0.0222953524966481 -0.0244979321305835"
        rpy="0 0 0" />
      <mass
        value="0.274585554808092" />
      <inertia
        ixx="0.000300911252684454"
        ixy="-3.32526758126057E-10"
        ixz="-1.11416777091271E-12"
        iyy="0.000561030263733097"
        iyz="-9.13022146247303E-06"
        izz="0.000323960029517023" />
    </inertial>
    <visual>
      <origin
        xyz="0 0 0"
        rpy="0 0 0" />
      <geometry>
        <mesh
          filename="package://ABOT/meshes/base_link.STL" />
      </geometry>
      <material
        name="">
        <color
          rgba="0.752941176470588 0.752941176470588 0.752941176470588 1" />
      </material>
    </visual>
    <collision>
      <origin
        xyz="0 0 0"
        rpy="0 0 0" />
      <geometry>
        <mesh
          filename="package://ABOT/meshes/base_link.STL" />
      </geometry>
    </collision>
  </link>
  <link
    name="abot_left_wheel">
    <inertial>
      <origin
        xyz="1.4324E-10 0.00056576 4.9274E-11"
        rpy="0 0 0" />
      <mass
        value="0.050464" />
      <inertia
        ixx="2.0701E-05"
        ixy="-1.8954E-14"
        ixz="-1.2393E-15"
        iyy="3.5827E-05"
        iyz="-1.8375E-14"
        izz="2.0701E-05" />
    </inertial>
    <visual>
      <origin
        xyz="0 0 0"
        rpy="0 0 0" />
      <geometry>
        <mesh
          filename="package://ABOT/meshes/abot_left_wheel.STL" />
      </geometry>
      <material
        name="">
        <color
          rgba="1 1 0 1" />
      </material>
    </visual>
    <collision>
      <origin
        xyz="0 0 0"
        rpy="0 0 0" />
      <geometry>
        <mesh
          filename="package://ABOT/meshes/abot_left_wheel.STL" />
      </geometry>
    </collision>
  </link>
  <joint
    name="left_wheel_to_base"
    type="continuous">
    <origin
      xyz="0.068 0 0.0145"
      rpy="0 -0.1987 -1.5708" />
    <parent
      link="base_link" />
    <child
      link="abot_left_wheel" />
    <axis
      xyz="0 1 0" />
  </joint>
  <link
    name="abot_right_wheel">
    <inertial>
      <origin
        xyz="1.92547728949513E-10 -0.000565763151060827 1.0414403540937E-10"
        rpy="0 0 0" />
      <mass
        value="0.0504636002883635" />
      <inertia
        ixx="2.07010058324571E-05"
        ixy="3.80886685919552E-14"
        ixz="-1.35840659411209E-15"
        iyy="3.58274339853362E-05"
        iyz="2.1837971288491E-15"
        izz="2.07008063139734E-05" />
    </inertial>
    <visual>
      <origin
        xyz="0 0 0"
        rpy="0 0 0" />
      <geometry>
        <mesh
          filename="package://ABOT/meshes/abot_right_wheel.STL" />
      </geometry>
      <material
        name="">
        <color
          rgba="1 1 0 1" />
      </material>
    </visual>
    <collision>
      <origin
        xyz="0 0 0"
        rpy="0 0 0" />
      <geometry>
        <mesh
          filename="package://ABOT/meshes/abot_right_wheel.STL" />
      </geometry>
    </collision>
  </link>
  <joint
    name="right_wheel_to_base"
    type="continuous">
    <origin
      xyz="-0.068 0 0.0145"
      rpy="0 0 -1.5708" />
    <parent
      link="base_link" />
    <child
      link="abot_right_wheel" />
    <axis
      xyz="0 1 0" />
  </joint>
  <link
    name="abot_caster_wheel">
    <inertial>
      <origin
        xyz="0 0 0"
        rpy="0 0 0" />
      <mass
        value="0" />
      <inertia
        ixx="0"
        ixy="0"
        ixz="0"
        iyy="0"
        iyz="0"
        izz="0" />
    </inertial>
    <visual>
      <origin
        xyz="0 0 0"
        rpy="0 0 0" />
      <geometry>
        <mesh
          filename="package://ABOT/meshes/abot_caster_wheel.STL" />
      </geometry>
      <material
        name="">
        <color
          rgba="1 1 1 1" />
      </material>
    </visual>
    <collision>
      <origin
        xyz="0 0 0"
        rpy="0 0 0" />
      <geometry>
        <mesh
          filename="package://ABOT/meshes/abot_caster_wheel.STL" />
      </geometry>
    </collision>
  </link>
  <joint
    name="caster_wheel_to_base"
    type="fixed">
    <origin
      xyz="0 0.078 -0.011"
      rpy="0 0 -1.5707963267949" />
    <parent
      link="base_link" />
    <child
      link="abot_caster_wheel" />
    <axis
      xyz="0 0 0" />
  </joint>
</robot>