<?xml version="1.0" encoding="utf-8"?>
<!-- This URDF was automatically created by SolidWorks to URDF Exporter! Originally created by Stephen Brawner (brawner@gmail.com) 
     Commit Version: 1.5.1-0-g916b5db  Build Version: 1.5.7152.31018
     For more information, please see http://wiki.ros.org/sw_urdf_exporter -->
<robot
  name="abot">
  <link
    name="abot_base">
    <inertial>
      <origin
        xyz="-0.024498 1.0952E-13 0.022295"
        rpy="0 0 0" />
      <mass
        value="0.27459" />
      <inertia
        ixx="0.00032396"
        ixy="-1.1142E-12"
        ixz="-9.1302E-06"
        iyy="0.00030091"
        iyz="-3.3253E-10"
        izz="0.00056103" />
    </inertial>
    <visual>
      <origin
        xyz="0 0 0"
        rpy="0 0 0" />
      <geometry>
        <mesh
          filename="package://abot/meshes/abot_base.STL" />
      </geometry>
      <material
        name="">
        <color
          rgba="0.75294 0.75294 0.75294 1" />
      </material>
    </visual>
    <collision>
      <origin
        xyz="0 0 0"
        rpy="0 0 0" />
      <geometry>
        <mesh
          filename="package://abot/meshes/abot_base.STL" />
      </geometry>
    </collision>
  </link>
  <link
    name="abot_left_wheel">
    <inertial>
      <origin
        xyz="1.9255E-10 0.00056576 -1.0414E-10"
        rpy="0 0 0" />
      <mass
        value="0.050464" />
      <inertia
        ixx="2.0701E-05"
        ixy="-3.8089E-14"
        ixz="1.3584E-15"
        iyy="3.5827E-05"
        iyz="2.1838E-15"
        izz="2.0701E-05" />
    </inertial>
    <visual>
      <origin
        xyz="0 0 0"
        rpy="0 0 0" />
      <geometry>
        <mesh
          filename="package://abot/meshes/abot_left_wheel.STL" />
      </geometry>
      <material
        name="">
        <color
          rgba="1 1 0 1" />
      </material>
    </visual>
    <collision>
      <origin
        xyz="0 0 0"
        rpy="0 0 0" />
      <geometry>
        <mesh
          filename="package://abot/meshes/abot_left_wheel.STL" />
      </geometry>
    </collision>
  </link>
  <joint
    name="left_wheel_to_base"
    type="continuous">
    <origin
      xyz="0 0.068 0.0145"
      rpy="0 0 0" />
    <parent
      link="abot_base" />
    <child
      link="abot_left_wheel" />
    <axis
      xyz="0 1 0" />
  </joint>
  <link
    name="abot_right_wheel">
    <inertial>
      <origin
        xyz="1.9255E-10 -0.00056576 1.0414E-10"
        rpy="0 0 0" />
      <mass
        value="0.050464" />
      <inertia
        ixx="2.0701E-05"
        ixy="3.8089E-14"
        ixz="-1.3584E-15"
        iyy="3.5827E-05"
        iyz="2.1838E-15"
        izz="2.0701E-05" />
    </inertial>
    <visual>
      <origin
        xyz="0 0 0"
        rpy="0 0 0" />
      <geometry>
        <mesh
          filename="package://abot/meshes/abot_right_wheel.STL" />
      </geometry>
      <material
        name="">
        <color
          rgba="1 1 0 1" />
      </material>
    </visual>
    <collision>
      <origin
        xyz="0 0 0"
        rpy="0 0 0" />
      <geometry>
        <mesh
          filename="package://abot/meshes/abot_right_wheel.STL" />
      </geometry>
    </collision>
  </link>
  <joint
    name="right_wheel_to_base"
    type="continuous">
    <origin
      xyz="0 -0.068 0.0145"
      rpy="0 0 0" />
    <parent
      link="abot_base" />
    <child
      link="abot_right_wheel" />
    <axis
      xyz="0 1 0" />
  </joint>
  <link
    name="abot_caster_wheel">
    <inertial>
      <origin
        xyz="0 1.6073E-19 0"
        rpy="0 0 0" />
      <mass
        value="0.011207" />
      <inertia
        ixx="2.1965E-07"
        ixy="-1.5533E-55"
        ixz="-1.9776E-56"
        iyy="2.1965E-07"
        iyz="-2.2674E-40"
        izz="2.1965E-07" />
    </inertial>
    <visual>
      <origin
        xyz="0 0 0"
        rpy="0 0 0" />
      <geometry>
        <mesh
          filename="package://abot/meshes/abot_caster_wheel.STL" />
      </geometry>
      <material
        name="">
        <color
          rgba="0.52941 0.54902 0.54902 1" />
      </material>
    </visual>
    <collision>
      <origin
        xyz="0 0 0"
        rpy="0 0 0" />
      <geometry>
        <mesh
          filename="package://abot/meshes/abot_caster_wheel.STL" />
      </geometry>
    </collision>
  </link>
  <joint
    name="caster_wheel_to_base"
    type="fixed">
    <origin
      xyz="-0.078 0 -0.011"
      rpy="0 0 0" />
    <parent
      link="abot_base" />
    <child
      link="abot_caster_wheel" />
    <axis
      xyz="0 0 0" />
  </joint>
</robot>