<?xml version="1.0" encoding="utf-8"?>
<!-- This URDF was automatically created by SolidWorks to URDF Exporter! Originally created by Stephen Brawner (brawner@gmail.com) 
     Commit Version: 1.5.1-0-g916b5db  Build Version: 1.5.7152.31018
     For more information, please see http://wiki.ros.org/sw_urdf_exporter -->
<robot
  name="abot">
  <link
    name="abot_base">
    <inertial>
      <origin
        xyz="-0.0208263382092977 -0.00168385933654572 0.0352033011756668"
        rpy="0 0 0" />
      <mass
        value="0.390932406092716" />
      <inertia
        ixx="0.000459913153601641"
        ixy="-1.71156077571516E-06"
        ixz="-9.21246691267104E-06"
        iyy="0.000422360494978724"
        iyz="-8.13604142628178E-09"
        izz="0.000815661246481602" />
    </inertial>
    <visual>
      <origin
        xyz="0 0 0"
        rpy="0 0 0" />
      <geometry>
        <mesh
          filename="package://abot/meshes/abot_base.STL" />
      </geometry>
      <material
        name="">
        <color
          rgba="0.752941176470588 0.752941176470588 0.752941176470588 1" />
      </material>
    </visual>
    <collision>
      <origin
        xyz="0 0 0"
        rpy="0 0 0" />
      <geometry>
        <mesh
          filename="package://abot/meshes/abot_base.STL" />
      </geometry>
    </collision>
  </link>
  <link
    name="abot_left_wheel">
    <inertial>
      <origin
        xyz="1.9255E-10 0.00056576 -1.0414E-10"
        rpy="0 0 0" />
      <mass
        value="0.050464" />
      <inertia
        ixx="2.0701E-05"
        ixy="-3.8089E-14"
        ixz="1.3584E-15"
        iyy="3.5827E-05"
        iyz="2.1838E-15"
        izz="2.0701E-05" />
    </inertial>
    <visual>
      <origin
        xyz="0 0 0"
        rpy="0 0 0" />
      <geometry>
        <mesh
          filename="package://abot/meshes/abot_left_wheel.STL" />
      </geometry>
      <material
        name="">
        <color
          rgba="1 1 0 1" />
      </material>
    </visual>
    <collision>
      <origin
        xyz="0 0 0"
        rpy="0 0 0" />
      <geometry>
        <mesh
          filename="package://abot/meshes/abot_left_wheel.STL" />
      </geometry>
    </collision>
  </link>
  <joint
    name="left_wheel_to_base"
    type="continuous">
    <origin
      xyz="0 0.068 0.0145"
      rpy="0 0 0" />
    <parent
      link="abot_base" />
    <child
      link="abot_left_wheel" />
    <axis
      xyz="0 1 0" />
  </joint>
  <link
    name="abot_right_wheel">
    <inertial>
      <origin
        xyz="1.925177854804E-10 -0.000565763151064075 1.04129900882488E-10"
        rpy="0 0 0" />
      <mass
        value="0.0504636002883635" />
      <inertia
        ixx="2.07010058324571E-05"
        ixy="3.80886687961463E-14"
        ixz="-1.3584077064374E-15"
        iyy="3.58274339853362E-05"
        iyz="2.18379796621346E-15"
        izz="2.07008063139734E-05" />
    </inertial>
    <visual>
      <origin
        xyz="0 0 0"
        rpy="0 0 0" />
      <geometry>
        <mesh
          filename="package://abot/meshes/abot_right_wheel.STL" />
      </geometry>
      <material
        name="">
        <color
          rgba="1 1 0 1" />
      </material>
    </visual>
    <collision>
      <origin
        xyz="0 0 0"
        rpy="0 0 0" />
      <geometry>
        <mesh
          filename="package://abot/meshes/abot_right_wheel.STL" />
      </geometry>
    </collision>
  </link>
  <joint
    name="right_wheel_to_base"
    type="continuous">
    <origin
      xyz="0 -0.068 0.0145"
      rpy="0 0 0" />
    <parent
      link="abot_base" />
    <child
      link="abot_right_wheel" />
    <axis
      xyz="0 1 0" />
  </joint>
  <link
    name="abot_caster_wheel">
    <inertial>
      <origin
        xyz="0 1.60734892388089E-19 0"
        rpy="0 0 0" />
      <mass
        value="0.0112066893138855" />
      <inertia
        ixx="2.19651110552156E-07"
        ixy="-1.55326461335414E-55"
        ixz="-1.97759730356012E-56"
        iyy="2.19651110552156E-07"
        iyz="-2.2674021764336E-40"
        izz="2.19651110552156E-07" />
    </inertial>
    <visual>
      <origin
        xyz="0 0 0"
        rpy="0 0 0" />
      <geometry>
        <mesh
          filename="package://abot/meshes/abot_caster_wheel.STL" />
      </geometry>
      <material
        name="">
        <color
          rgba="0.529411764705882 0.549019607843137 0.549019607843137 1" />
      </material>
    </visual>
    <collision>
      <origin
        xyz="0 0 0"
        rpy="0 0 0" />
      <geometry>
        <mesh
          filename="package://abot/meshes/abot_caster_wheel.STL" />
      </geometry>
    </collision>
  </link>
  <joint
    name="caster_wheel_to_base"
    type="fixed">
    <origin
      xyz="-0.078 0 -0.011"
      rpy="0 0 0" />
    <parent
      link="abot_base" />
    <child
      link="abot_caster_wheel" />
    <axis
      xyz="0 1 0" />
  </joint>
</robot>